Workbook

Sheet PERSONAL DE LA ESFM
A2: ESFM "SIMON BOLIVAR" CORORO
A3: PERSONAL DIRECTIVO
A4: N° | B4: N° | C4: APELLIDOS Y NOMBRES | D4: N° C.I | E4: CARGO | F4: N° CELULAR
A5: 1 | B5: 1 | C5: QUISPE RICALDE SAUL | D5: 8550592 | E5: DIRECTOR GENERAL | F5: 72868752
A6: 2 | B6: 2 | C6: CALLAPA CRUZ ARMIN | D6: 5114078 | E6: DIRECTOR ACADÉMICO | F6: 72446018
A7: 3 | B7: 3 | C7: ESPADA ARAMAYO LIZBETH CRISTEL | D7: 10422557 | E7: DIRECTORA ADMINISTRATIVA FINANCIERA | F7: 78680813
A8: 4 | B8: 4 | C8: DURAN LOMAR ALBERTO | D8: 5668698 | E8: ASESOR LEGAL | F8: 70332321
A9: 5 | B9: 5 | C9: SAAVEDRA SALAZAR DIEGO | D9: 1096700 | E9: COORDINADOR ACADEMICO IEPC - PEC | F9: 69609980
A10: PERSONAL DOCENTE | B10: PERSONAL DOCENTE
A11: N° | B11: N° | C11: APELLIDOS Y NOMBRES | D11: N° C.I | E11: CARGO | F11: N° CELULAR
A12: 6 | B12: 1 | C12: ARIAS CAYO ZULMA ABIGAIL | D12: 6681389 | E12: DOCENTE - RESPONSABLE BIENTESTAR ESTUDIANTIL | F12: 73607386
A13: 7 | B13: 2 | C13: CALLE REQUENA GUILLERMINA LUZ | D13: 3093595 | E13: DOCENTE LENGUA EXTRANJERA (INGLES) | F13: 71888867
A14: 8 | B14: 3 | C14: ILAFAYA CORONADO CLAUDIA | D14: 5669075 | E14: DOCENTE DE EDUCACIÓN PRIMARIA COMUNITARIA VOCACIONAL | F14: 73440745
A15: 9 | B15: 4 | C15: MACHACA MOLLO ELVIS JHONATHAN | D15: 8592488 | E15: DOCENTE DE ARTES PLÁSTICAS Y VISUALES | F15: 61827879
A16: 10 | B16: 5 | C16: MEDRANO QUISPE RUTH ELIZABETH | D16: 1099917 | E16: DOCENTE INTERPRETE | F16: 68647647
A17: 11 | B17: 6 | C17: MENDOZA MOYA YOLANDA | D17: 4095694 | E17: DOCENTE DE EDUCACIÓN PRIMARIA COMUNITARIA VOCACIONAL | F17: 69665520
A18: 12 | B18: 7 | C18: ZAMBRANA QUIÑONES SANDRA | D18: 4008329 | E18: DOCENTE DE EDUCACIÓN INICIAL EN FAMILIA COMUNITARIA | F18: 79437979
B19: 8 | C19: TERRAZAS VELASQUEZ RAUL | D19: 7485109 | E19: DOCENTE DE ÁREA PRODUCTIVA | F19: 67725671
A20: 13 | B20: 9 | C20: QUISPE OLMEDO LEONARDO ARIEL | D20: 6674548 | E20: DOCENTE DE INVESTIGACIÓN | F20: 70337441
A21: 14 | B21: 10 | C21: RAMIREZ FERNANDEZ NANCY | D21: 3658072 | E21: DOCENTE DE LENGUA ORIGINARIA | F21: 73463508
A22: 15 | B22: 11 | C22: RAMOS SANCHEZ DELFIN | D22: 1276103 | E22: DOCENTE DE MATEMÁTICA | F22: 71154656
A23: 16 | B23: 12 | C23: RIVERA QUISPE MARY ROSA DEL CARMEN | D23: 3663169 | E23: DOCENTE DE EDUCACIÓN PRIMARIA COMUNITARIA VOCACIONAL | F23: 73420946
A24: 17 | B24: 13 | C24: ALVAREZ DORYS MABEL | D24: 5640024 | E24: DOCENTE DE EDUCACIÓN PRIMARIA COMUNITARIA VOCACIONAL | F24: 72872205
A25: 20 | B25: 14 | C25: TORRES ORTUÑO PAMELA | D25: 7567785 | E25: DOCENTE DE ARTES PLÁSTICAS Y VISUALES | F25: 73434221
A26: 21 | B26: 15 | C26: YUCRA CRUZ SATURNINA | D26: 5506447 | E26: DOCENTE DE EDUCACIÓN INICIAL EN FAMILIA COMUNITARIA | F26: 73873917
A27: PERSONAL ADMINISTRATIVO | B27: PERSONAL ADMINISTRATIVO
A28: N° | B28: N° | C28: APELLIDOS Y NOMBRES | D28: N° C.I | E28: CARGO | F28: N° CELULAR
A29: 22 | B29: 1 | C29: SEGOVIA CRUZ GISELLE TIFFANI | D29: 8522868 | E29: RESPONSABLE DE BIENES Y SERVICIOS | F29: 72410345
A30: 23 | B30: 2 | C30: . ESPINOZA RUTH PAMELA | D30: 12621864 | E30: SECRETARIA DE DIRECCIÓN ACADEMICA | F30: 71673609
A31: 24 | B31: 3 | C31: VACA CONCHERI EMELIT | D31: 12456683 | E31: SECRETARIO DE DIRECCIÓN GENERAL | F31: 71153990
A32: 25 | B32: 4 | C32: FUERTES ROMERO NICANOR | D32: 3627106 | E32: RESPONSABLE DE KARDEX Y SISTEMAS | F32: 72864689
A33: 26 | B33: 5 | C33: DURAN RADA DIRZA XIMENA | D33: 9146494 | E33: SECRETARIO DE DIRECCIÓN ADMINSITRATIVA FINANCIERA | F33: 73444883
A34: 27 | B34: 6 | C34: MOREIRA MAMANI JHENNY MARIELA | D34: 7513057 | E34: RESPONSABLE DE SALUD PREVENTIVA | F34: 72316002
A35: 28 | B35: 7 | C35: PEREZ GUERRA CARLOS MANUEL | D35: 10342838 | E35: RESPONSABLE DE PRESUPUESTO Y CONTABILIDAD | F35: 68640802
A36: 29 | B36: 8 | C36: SENO ALDANA TEOFILO JORGE | D36: 4631528 | E36: TÉCNICO DE BIBLIOTECA | F36: 72896333
A37: 30 | B37: 9 | C37: CAMAARGO MARCA EDWARD | D37: 7486511 | E37: TÉCNICO DE SISTEMAS Y SOPORTE INFORMÁTICO | F37: 79310777
A38: 31 | B38: 10 | C38: CARDENAS ZARATE CLAUDIA VANESA | D38: 8590352 | E38: TECNICO CAJERA | F38: 60488957
A39: PERSONAL DE SERVICIO | B39: PERSONAL DE SERVICIO
A40: N° | B40: N° | C40: APELLIDOS Y NOMBRES | D40: N° C.I | E40: CARGO | F40: N° CELULAR
A41: 32 | B41: 1 | C41: CALDERON CASTELLON FERNANDO | D41: 4109228 | E41: SERVICIOS MÚLTIPLES | F41: 72871384
...

Sheet PARTICIPANTES EN LA CUMBRE
A1: NOMINA DE ASISTENTES A LA CUMBRE EDUCATIVA - CORORO
A2: N° | B2: APELLIDOS Y NOMBRES | C2: N° C.I
A3: 1 | B3: QUISPE RICALDE SAUL | C3: 8550592
A4: 2 | B4: CALLAPA CRUZ ARMIN | C4: 5114078
A5: 3 | B5: ESPADA ARAMAYO LIZBETH CRISTEL | C5: 10422557
A6: 4 | B6: DURAN LOMAR ALBERTO | C6: 5668698
A7: 5 | B7: SAAVEDRA SALAZAR DIEGO | C7: 1096700
B8: PERSONAL DOCENTE
A9: 6 | B9: ARIAS CAYO ZULMA ABIGAIL | C9: 6681389
A10: 7 | B10: CALLE REQUENA GUILLERMINA LUZ | C10: 3093595
A11: 8 | B11: ILAFAYA CORONADO CLAUDIA | C11: 5669075
A12: 9 | B12: MACHACA MOLLO ELVIS JHONATHAN | C12: 8592488
A13: 10 | B13: MEDRANO QUISPE RUTH ELIZABETH | C13: 1099917
A14: 11 | B14: MENDOZA MOYA YOLANDA | C14: 4095964
A15: 12 | B15: RAMOS SANCHEZ DELFIN
A16: 13 | B16: QUISPE OLMEDO LEONARDO ARIEL | C16: 6674548
A17: 14 | B17: RAMIREZ FERNANDEZ NANCY | C17: 3658072
A18: 15 | B18: RIVERA QUISPE MARY ROSA DEL CARMEN | C18: 3663169
A19: 16 | B19: RODAS VASQUEZ ARNULFO | C19: 5639592
A20: 17 | B20: SALVADOR QUISPE DELFIN | C20: 5085012
A21: 18 | B21: TARDIO CONDORI MARIBEL | C21: 5668415
A22: 19 | B22: YUCRA CRUZ SATURNINA | C22: 5506447
B23: PERSONAL ADMINISTRATIVO
A24: 20 | B24: . CASTELLON MARLENE | C24: 10422206
A25: 21 | B25: . ESPINOZA RUTH PAMELA | C25: 12621864
A26: 22 | B26: FRIAS VALLEJOS RAMIRO ALEX | C26: 10384527
A27: 23 | B27: FUERTES ROMERO NICANOR | C27: 3627106
A28: 24 | B28: MOREIRA MAMANI JHENNY MARIELA | C28: 7513057
A29: 25 | B29: LEON PERALTA ELSA NOEMI | C29: 12516700
A30: 26 | B30: PEREZ GUERRA CARLOS MANUEL | C30: 10342838
A31: 27 | B31: SENO ALDANA TEOFILO JORGE | C31: 4631528
A32: 28 | B32: VILLARPANDO MAMANI ALISON | C32: 10349893
B33: PERSONAL DE SERVICIO
A34: 29 | B34: CALDERON CASTELLON FERNANDO | C34: 4109228
A35: 30 | B35: FERNANDEZ VELA JUAN | C35: 4149533
A36: 31 | B36: FLORES CARRILLO SEVERINA | C36: 10315882
A37: 32 | B37: HUARACHI CHUMACERO RODOLFO | C37: 5556739
A38: 33 | B38: MARTINEZ ORTIZ EUGENIA | C38: 5697980
A39: 34 | B39: PANTOJA ARANCIBIA JUSTINO | C39: 3307619
B40: ESTUDIANTES
...

Sheet CUMPLEAÑOS
B3: FECHAS DE NACIMIENTO | I3: 46022
B4: N° | C4: APELLIDOS Y NOMBRES | D4: FECHA | E4: E | F4: D | G4: M | H4: A | I4: EE
B5: 1 | C5: FLORES CARRILLO SEVERINA | D5: 24838 | E5: =(TODAY()-D5)/365 -> 58.224658 | F5: 1 | G5: 1 | H5: 1968 | I5: =($I$3-D5)/365 -> 58.038356
B6: 2 | C6: RAMIREZ FERNANDEZ NANCY | D6: 29225 | E6: =(TODAY()-D6)/365 -> 46.205479 | F6: 5 | G6: 1 | H6: 1980 | I6: =($I$3-D6)/365 -> 46.019178
B7: 3 | C7: MORENO ESCOBAR GLADYS MARIA | D7: 30724 | E7: =(TODAY()-D7)/365 -> 42.09863 | F7: 12 | G7: 2 | H7: 1984 | I7: =($I$3-D7)/365 -> 41.912329
B8: 4 | C8: SALVADOR QUISPE DELFIN | D8: 28902 | E8: =(TODAY()-D8)/365 -> 47.090411 | F8: 16 | G8: 2 | H8: 1979 | I8: =($I$3-D8)/365 -> 46.90411
B9: 5 | C9: MEDRANO QUISPE RUTH ELIZABETH | D9: 24173 | E9: =(TODAY()-D9)/365 -> 60.046575 | F9: 7 | G9: 3 | H9: 1966 | I9: =($I$3-D9)/365 -> 59.860274
B10: 6 | C10: MENDOZA MOYA YOLANDA | D10: 28561 | E10: =(TODAY()-D10)/365 -> 48.024658 | F10: 12 | G10: 3 | H10: 1978 | I10: =($I$3-D10)/365 -> 47.838356
B11: 7 | C11: MOREIRA MAMANI JHENNY MARIELA | D11: 33678 | E11: =(TODAY()-D11)/365 -> 34.005479 | F11: 15 | G11: 3 | H11: 1992 | I11: =($I$3-D11)/365 -> 33.819178
B12: 8 | C12: ESPINOZA RUTH PAMELA | D12: 33320 | E12: =(TODAY()-D12)/365 -> 34.986301 | F12: 23 | G12: 3 | H12: 1991 | I12: =($I$3-D12)/365 -> 34.8
B13: 9 | C13: MACHACA MOLLO ELVIS JHONATHAN | D13: 33701 | E13: =(TODAY()-D13)/365 -> 33.942466 | F13: 7 | G13: 4 | H13: 1992 | I13: =($I$3-D13)/365 -> 33.756164
B14: 10 | C14: SENO ALDANA TEOFILO JORGE | D14: 26781 | E14: =(TODAY()-D14)/365 -> 52.90137 | F14: 27 | G14: 4 | H14: 1973 | I14: =($I$3-D14)/365 -> 52.715068
B15: 11 | C15: ARIAS CAYO ZULMA ABIGAIL | D15: 32263 | E15: =(TODAY()-D15)/365 -> 37.882192 | F15: 30 | G15: 4 | H15: 1988 | I15: =($I$3-D15)/365 -> 37.69589
B16: 12 | C16: TORRES ORTUÑO PAMELA | D16: 33359 | E16: =(TODAY()-D16)/365 -> 34.879452 | F16: 1 | G16: 5 | H16: 1991 | I16: =($I$3-D16)/365 -> 34.693151
... B42: 38 | C42: FRIAS VALLEJOS RAMIRO ALEX | D42: 35429 | E42: =(TODAY()-D42)/365 -> 29.208219 | F42: 30 | G42: 12 | H42: 1996 | I42: =($I$3-D42)/365 -> 29.021918

Sheet ASISTENCIA 1
A2: FECHA DE ACTIVIDAD O REUNIÓN | E2: Miercoles, 25/02/2025 | F2: Martes, 6/5/2025 | G2: miercoles, 13/5/2025 | AB2: PRESENTE | AC2: ATRASO | AD2: LICENCIA | AE2: FALTA | AF2: TOTAL
A3: PERSONAL DIRECTIVO
A4: N° | B4: APELLIDOS Y NOMBRES | AB4: P | AC4: A | AD4: L | AE4: F | AF4: T
A5: 1 | B5: QUISPE RICALDE SAUL | E5: P | F5: P | G5: P | AB5: =COUNTIF(C5:AA5,$AB$4) -> 3 | AC5: =COUNTIF(C5:AA5,$AC$4) -> 0 | AD5: =COUNTIF(C5:AA5,$AD$4) -> 0 | AE5: =COUNTIF(C5:AA5,$AE$4) -> 0 | AF5: =SUM(AB5:AE5) -> 3
A6: 2 | B6: CALLAPA CRUZ ARMIN | E6: P | F6: P | G6: P | AB6: =COUNTIF(C6:AA6,$AB$4) -> 3 | AC6: =COUNTIF(C6:AA6,$AC$4) -> 0 | AD6: =COUNTIF(C6:AA6,$AD$4) -> 0 | AE6: =COUNTIF(C6:AA6,$AE$4) -> 0 | AF6: =SUM(AB6:AE6) -> 3
A7: 3 | B7: ESPADA ARAMAYO LIZBETH CRISTEL | E7: P | F7: P | G7: P | AB7: =COUNTIF(C7:AA7,$AB$4) -> 3 | AC7: =COUNTIF(C7:AA7,$AC$4) -> 0 | AD7: =COUNTIF(C7:AA7,$AD$4) -> 0 | AE7: =COUNTIF(C7:AA7,$AE$4) -> 0 | AF7: =SUM(AB7:AE7) -> 3
A8: 4 | B8: DURAN LOMAR ALBERTO | E8: P | F8: P | G8: P | AB8: =COUNTIF(C8:AA8,$AB$4) -> 3 | AC8: =COUNTIF(C8:AA8,$AC$4) -> 0 | AD8: =COUNTIF(C8:AA8,$AD$4) -> 0 | AE8: =COUNTIF(C8:AA8,$AE$4) -> 0 | AF8: =SUM(AB8:AE8) -> 3
A9: 5 | B9: SAAVEDRA SALAZAR DIEGO | E9: P | F9: P | G9: A | AB9: =COUNTIF(C9:AA9,$AB$4) -> 2 | AC9: =COUNTIF(C9:AA9,$AC$4) -> 1 | AD9: =COUNTIF(C9:AA9,$AD$4) -> 0 | AE9: =COUNTIF(C9:AA9,$AE$4) -> 0 | AF9: =SUM(AB9:AE9) -> 3
A10: PERSONAL DOCENTE
A11: 1 | B11: ARIAS CAYO ZULMA ABIGAIL | E11: P | F11: P | G11: P | AB11: =COUNTIF(C11:AA11,$AB$4) -> 3 | AC11: =COUNTIF(C11:AA11,$AC$4) -> 0 | AD11: =COUNTIF(C11:AA11,$AD$4) -> 0 | AE11: =COUNTIF(C11:AA11,$AE$4) -> 0 | AF11: =SUM(AB11:AE11) -> 3
A12: 2 | B12: CALLE REQUENA GUILLERMINA LUZ | E12: P | F12: A | G12: A | AB12: =COUNTIF(C12:AA12,$AB$4) -> 1 | AC12: =COUNTIF(C12:AA12,$AC$4) -> 2 | AD12: =COUNTIF(C12:AA12,$AD$4) -> 0 | AE12: =COUNTIF(C12:AA12,$AE$4) -> 0 | AF12: =SUM(AB12:AE12) -> 3
A13: 3 | B13: ILAFAYA CORONADO CLAUDIA | E13: P | F13: P | G13: A | AB13: =COUNTIF(C13:AA13,$AB$4) -> 2 | AC13: =COUNTIF(C13:AA13,$AC$4) -> 1 | AD13: =COUNTIF(C13:AA13,$AD$4) -> 0 | AE13: =COUNTIF(C13:AA13,$AE$4) -> 0 | AF13: =SUM(AB13:AE13) -> 3
A14: 4 | B14: MACHACA MOLLO ELVIS JHONATHAN | E14: P | F14: P | G14: P | AB14: =COUNTIF(C14:AA14,$AB$4) -> 3 | AC14: =COUNTIF(C14:AA14,$AC$4) -> 0 | AD14: =COUNTIF(C14:AA14,$AD$4) -> 0 | AE14: =COUNTIF(C14:AA14,$AE$4) -> 0 | AF14: =SUM(AB14:AE14) -> 3
A15: 5 | B15: MEDRANO QUISPE RUTH ELIZABETH | E15: P | F15: L | G15: P | AB15: =COUNTIF(C15:AA15,$AB$4) -> 2 | AC15: =COUNTIF(C15:AA15,$AC$4) -> 0 | AD15: =COUNTIF(C15:AA15,$AD$4) -> 1 | AE15: =COUNTIF(C15:AA15,$AE$4) -> 0 | AF15: =SUM(AB15:AE15) -> 3
A16: 6 | B16: MENDOZA MOYA YOLANDA | E16: A | F16: P | G16: A | AB16: =COUNTIF(C16:AA16,$AB$4) -> 1 | AC16: =COUNTIF(C16:AA16,$AC$4) -> 2 | AD16: =COUNTIF(C16:AA16,$AD$4) -> 0 | AE16: =COUNTIF(C16:AA16,$AE$4) -> 0 | AF16: =SUM(AB16:AE16) -> 3
A17: 7 | B17: MORENO ESCOBAR GLADYS MARIA | F17: P | G17: P | AB17: =COUNTIF(C17:AA17,$AB$4) -> 2 | AC17: =COUNTIF(C17:AA17,$AC$4) -> 0 | AD17: =COUNTIF(C17:AA17,$AD$4) -> 0 | AE17: =COUNTIF(C17:AA17,$AE$4) -> 0 | AF17: =SUM(AB17:AE17) -> 2
A18: 8 | B18: ORDOÑEZ ACEBO ELIAS JUSTO
A19: 9 | B19: QUISPE OLMEDO LEONARDO ARIEL | E19: P | F19: P | G19: P | AB19: =COUNTIF(C19:AA19,$AB$4) -> 3 | AC19: =COUNTIF(C19:AA19,$AC$4) -> 0 | AD19: =COUNTIF(C19:AA19,$AD$4) -> 0 | AE19: =COUNTIF(C19:AA19,$AE$4) -> 0 | AF19: =SUM(AB19:AE19) -> 3
A20: 10 | B20: RAMIREZ FERNANDEZ NANCY | E20: P | F20: P | G20: P | AB20: =COUNTIF(C20:AA20,$AB$4) -> 3 | AC20: =COUNTIF(C20:AA20,$AC$4) -> 0 | AD20: =COUNTIF(C20:AA20,$AD$4) -> 0 | AE20: =COUNTIF(C20:AA20,$AE$4) -> 0 | AF20: =SUM(AB20:AE20) -> 3
A21: 11 | B21: RAMOS SANCHEZ DELFIN | E21: P | F21: P | G21: P | AB21: =COUNTIF(C21:AA21,$AB$4) -> 3 | AC21: =COUNTIF(C21:AA21,$AC$4) -> 0 | AD21: =COUNTIF(C21:AA21,$AD$4) -> 0 | AE21: =COUNTIF(C21:AA21,$AE$4) -> 0 | AF21: =SUM(AB21:AE21) -> 3
A22: 12 | B22: RIVERA QUISPE MARY ROSA DEL CARMEN | E22: P | F22: P | G22: P | AB22: =COUNTIF(C22:AA22,$AB$4) -> 3 | AC22: =COUNTIF(C22:AA22,$AC$4) -> 0 | AD22: =COUNTIF(C22:AA22,$AD$4) -> 0 | AE22: =COUNTIF(C22:AA22,$AE$4) -> 0 | AF22: =SUM(AB22:AE22) -> 3
A23: 13 | B23: RODAS VASQUEZ ARNULFO | E23: P | F23: P | G23: P | AB23: =COUNTIF(C23:AA23,$AB$4) -> 3 | AC23: =COUNTIF(C23:AA23,$AC$4) -> 0 | AD23: =COUNTIF(C23:AA23,$AD$4) -> 0 | AE23: =COUNTIF(C23:AA23,$AE$4) -> 0 | AF23: =SUM(AB23:AE23) -> 3
A24: 14 | B24: SALVADOR QUISPE DELFIN | E24: P | F24: A | G24: P | AB24: =COUNTIF(C24:AA24,$AB$4) -> 2 | AC24: =COUNTIF(C24:AA24,$AC$4) -> 1 | AD24: =COUNTIF(C24:AA24,$AD$4) -> 0 | AE24: =COUNTIF(C24:AA24,$AE$4) -> 0 | AF24: =SUM(AB24:AE24) -> 3
A25: 15 | B25: TARDIO CONDORI MARIBEL | E25: P | F25: P | G25: P | AB25: =COUNTIF(C25:AA25,$AB$4) -> 3 | AC25: =COUNTIF(C25:AA25,$AC$4) -> 0 | AD25: =COUNTIF(C25:AA25,$AD$4) -> 0 | AE25: =COUNTIF(C25:AA25,$AE$4) -> 0 | AF25: =SUM(AB25:AE25) -> 3
A26: 16 | B26: TORRES ORTUÑO PAMELA | E26: P | F26: P | G26: P | AB26: =COUNTIF(C26:AA26,$AB$4) -> 3 | AC26: =COUNTIF(C26:AA26,$AC$4) -> 0 | AD26: =COUNTIF(C26:AA26,$AD$4) -> 0 | AE26: =COUNTIF(C26:AA26,$AE$4) -> 0 | AF26: =SUM(AB26:AE26) -> 3
A27: 17 | B27: YUCRA CRUZ SATURNINA | F27: P | G27: P | AB27: =COUNTIF(C27:AA27,$AB$4) -> 2 | AC27: =COUNTIF(C27:AA27,$AC$4) -> 0 | AD27: =COUNTIF(C27:AA27,$AD$4) -> 0 | AE27: =COUNTIF(C27:AA27,$AE$4) -> 0 | AF27: =SUM(AB27:AE27) -> 2
A28: 18 | B28: INICIAL 3 | AB28: =COUNTIF(C28:AA28,$AB$4) -> 0 | AC28: =COUNTIF(C28:AA28,$AC$4) -> 0 | AD28: =COUNTIF(C28:AA28,$AD$4) -> 0 | AE28: =COUNTIF(C28:AA28,$AE$4) -> 0 | AF28: =SUM(AB28:AE28) -> 0
A29: PERSONAL ADMINISTRATIVO
A30: 1 | B30: . CASTELLON MARLENE | E30: P | F30: P | G30: P | AB30: =COUNTIF(C30:AA30,$AB$4) -> 3 | AC30: =COUNTIF(C30:AA30,$AC$4) -> 0 | AD30: =COUNTIF(C30:AA30,$AD$4) -> 0 | AE30: =COUNTIF(C30:AA30,$AE$4) -> 0 | AF30: =SUM(AB30:AE30) -> 3
A31: 2 | B31: . ESPINOZA RUTH PAMELA | E31: P | F31: P | G31: P | AB31: =COUNTIF(C31:AA31,$AB$4) -> 3 | AC31: =COUNTIF(C31:AA31,$AC$4) -> 0 | AD31: =COUNTIF(C31:AA31,$AD$4) -> 0 | AE31: =COUNTIF(C31:AA31,$AE$4) -> 0 | AF31: =SUM(AB31:AE31) -> 3
A32: 3 | B32: FRIAS VALLEJOS RAMIRO ALEX | E32: P | F32: P | G32: P | AB32: =COUNTIF(C32:AA32,$AB$4) -> 3 | AC32: =COUNTIF(C32:AA32,$AC$4) -> 0 | AD32: =COUNTIF(C32:AA32,$AD$4) -> 0 | AE32: =COUNTIF(C32:AA32,$AE$4) -> 0 | AF32: =SUM(AB32:AE32) -> 3
A33: 4 | B33: FUERTES ROMERO NICANOR | E33: P | F33: P | G33: P | AB33: =COUNTIF(C33:AA33,$AB$4) -> 3 | AC33: =COUNTIF(C33:AA33,$AC$4) -> 0 | AD33: =COUNTIF(C33:AA33,$AD$4) -> 0 | AE33: =COUNTIF(C33:AA33,$AE$4) -> 0 | AF33: =SUM(AB33:AE33) -> 3
A34: 5 | B34: LEON PERALTA ELSA NOEMI | F34: P | G34: P | AB34: =COUNTIF(C34:AA34,$AB$4) -> 2 | AC34: =COUNTIF(C34:AA34,$AC$4) -> 0 | AD34: =COUNTIF(C34:AA34,$AD$4) -> 0 | AE34: =COUNTIF(C34:AA34,$AE$4) -> 0 | AF34: =SUM(AB34:AE34) -> 2
A35: 6 | B35: MOREIRA MAMANI JHENNY MARIELA | F35: P | G35: P | AB35: =COUNTIF(C35:AA35,$AB$4) -> 2 | AC35: =COUNTIF(C35:AA35,$AC$4) -> 0 | AD35: =COUNTIF(C35:AA35,$AD$4) -> 0 | AE35: =COUNTIF(C35:AA35,$AE$4) -> 0 | AF35: =SUM(AB35:AE35) -> 2
A36: 7 | B36: PEREZ GUERRA CARLOS MANUEL | E36: P | F36: P | G36: P | AB36: =COUNTIF(C36:AA36,$AB$4) -> 3 | AC36: =COUNTIF(C36:AA36,$AC$4) -> 0 | AD36: =COUNTIF(C36:AA36,$AD$4) -> 0 | AE36: =COUNTIF(C36:AA36,$AE$4) -> 0 | AF36: =SUM(AB36:AE36) -> 3
A37: 8 | B37: SENO ALDANA TEOFILO JORGE | E37: P | F37: P | G37: P | AB37: =COUNTIF(C37:AA37,$AB$4) -> 3 | AC37: =COUNTIF(C37:AA37,$AC$4) -> 0 | AD37: =COUNTIF(C37:AA37,$AD$4) -> 0 | AE37: =COUNTIF(C37:AA37,$AE$4) -> 0 | AF37: =SUM(AB37:AE37) -> 3
B38: QUISPE LEVA TEODORO | E38: P | F38: P | G38: P | AB38: =COUNTIF(C38:AA38,$AB$4) -> 3 | AC38: =COUNTIF(C38:AA38,$AC$4) -> 0 | AD38: =COUNTIF(C38:AA38,$AD$4) -> 0 | AE38: =COUNTIF(C38:AA38,$AE$4) -> 0 | AF38: =SUM(AB38:AE38) -> 3
B39: VILLARPANDO MAMANI ALISON | E39: P | F39: P | G39: P | AB39: =COUNTIF(C39:AA39,$AB$4) -> 3 | AC39: =COUNTIF(C39:AA39,$AC$4) -> 0 | AD39: =COUNTIF(C39:AA39,$AD$4) -> 0 | AE39: =COUNTIF(C39:AA39,$AE$4) -> 0 | AF39: =SUM(AB39:AE39) -> 3
A40: PERSONAL DE SERVICIO
A41: 1 | B41: CALDERON CASTELLON FERNANDO | E41: A | F41: P | G41: P | AB41: =COUNTIF(C41:AA41,$AB$4) -> 2 | AC41: =COUNTIF(C41:AA41,$AC$4) -> 1 | AD41: =COUNTIF(C41:AA41,$AD$4) -> 0 | AE41: =COUNTIF(C41:AA41,$AE$4) -> 0 | AF41: =SUM(AB41:AE41) -> 3
...

Sheet ASIS_SINDICATO
A1: FECHA DE ACTIVIDAD O REUNIÓN | P1: PRESENTE | Q1: ATRASO | R1: LICENCIA | S1: FALTA | T1: TOTAL
A2: PERSONAL DIRECTIVO
A3: N° | B3: APELLIDOS Y NOMBRES | C3: ___ | D3: ___2 | E3: ___3 | F3: ___4 | G3: ___5 | H3: ___12 | I3: ___125 | J3: ___124 | K3: ___123 | L3: ___122 | M3: ___13 | N3: ___14 | O3: ___15 | P3: P | Q3: A2 | R3: L | S3: F | T3: T
A4: 1 | B4: QUISPE RICALDE SAUL | P4: =COUNTIF(C4:O4,$P$4) -> 0 | Q4: =COUNTIF(C4:O4,$Q$4) -> 0 | R4: =COUNTIF(C4:O4,$R$4) -> 0 | S4: =COUNTIF(C4:O4,$S$4) -> 0 | T4: =SUM(P4:S4) -> 0
A5: 2 | B5: CALLAPA CRUZ ARMIN | P5: =COUNTIF(C5:O5,$P$4) -> 0 | Q5: =COUNTIF(C5:O5,$Q$4) -> 0 | R5: =COUNTIF(C5:O5,$R$4) -> 0 | S5: =COUNTIF(C5:O5,$S$4) -> 0 | T5: =SUM(P5:S5) -> 0
A6: 3 | B6: ESPADA ARAMAYO LIZBETH CRISTEL | P6: =COUNTIF(C6:O6,$P$4) -> 0 | Q6: =COUNTIF(C6:O6,$Q$4) -> 0 | R6: =COUNTIF(C6:O6,$R$4) -> 0 | S6: =COUNTIF(C6:O6,$S$4) -> 0 | T6: =SUM(P6:S6) -> 0
A7: 4 | B7: DURAN LOMAR ALBERTO | P7: =COUNTIF(C7:O7,$P$4) -> 0 | Q7: =COUNTIF(C7:O7,$Q$4) -> 0 | R7: =COUNTIF(C7:O7,$R$4) -> 0 | S7: =COUNTIF(C7:O7,$S$4) -> 0 | T7: =SUM(P7:S7) -> 0
A8: 5 | B8: SAAVEDRA SALAZAR DIEGO | P8: =COUNTIF(C8:O8,$P$4) -> 0 | Q8: =COUNTIF(C8:O8,$Q$4) -> 0 | R8: =COUNTIF(C8:O8,$R$4) -> 0 | S8: =COUNTIF(C8:O8,$S$4) -> 0 | T8: =SUM(P8:S8) -> 0
A9: PERSONAL DOCENTE
A10: 1 | B10: ARIAS CAYO ZULMA ABIGAIL | P10: =COUNTIF(C10:O10,$P$4) -> 0 | Q10: =COUNTIF(C10:O10,$Q$4) -> 0 | R10: =COUNTIF(C10:O10,$R$4) -> 0 | S10: =COUNTIF(C10:O10,$S$4) -> 0 | T10: =SUM(P10:S10) -> 0
A11: 2 | B11: CALLE REQUENA GUILLERMINA LUZ | P11: =COUNTIF(C11:O11,$P$4) -> 0 | Q11: =COUNTIF(C11:O11,$Q$4) -> 0 | R11: =COUNTIF(C11:O11,$R$4) -> 0 | S11: =COUNTIF(C11:O11,$S$4) -> 0 | T11: =SUM(P11:S11) -> 0
A12: 3 | B12: ILAFAYA CORONADO CLAUDIA | P12: =COUNTIF(C12:O12,$P$4) -> 0 | Q12: =COUNTIF(C12:O12,$Q$4) -> 0 | R12: =COUNTIF(C12:O12,$R$4) -> 0 | S12: =COUNTIF(C12:O12,$S$4) -> 0 | T12: =SUM(P12:S12) -> 0
A13: 4 | B13: MACHACA MOLLO ELVIS JHONATHAN | P13: =COUNTIF(C13:O13,$P$4) -> 0 | Q13: =COUNTIF(C13:O13,$Q$4) -> 0 | R13: =COUNTIF(C13:O13,$R$4) -> 0 | S13: =COUNTIF(C13:O13,$S$4) -> 0 | T13: =SUM(P13:S13) -> 0
A14: 5 | B14: MEDRANO QUISPE RUTH ELIZABETH | P14: =COUNTIF(C14:O14,$P$4) -> 0 | Q14: =COUNTIF(C14:O14,$Q$4) -> 0 | R14: =COUNTIF(C14:O14,$R$4) -> 0 | S14: =COUNTIF(C14:O14,$S$4) -> 0 | T14: =SUM(P14:S14) -> 0
A15: 6 | B15: MENDOZA MOYA YOLANDA | P15: =COUNTIF(C15:O15,$P$4) -> 0 | Q15: =COUNTIF(C15:O15,$Q$4) -> 0 | R15: =COUNTIF(C15:O15,$R$4) -> 0 | S15: =COUNTIF(C15:O15,$S$4) -> 0 | T15: =SUM(P15:S15) -> 0
A16: 7 | B16: QUISPE OLMEDO LEONARDO ARIEL | P16: =COUNTIF(C16:O16,$P$4) -> 0 | Q16: =COUNTIF(C16:O16,$Q$4) -> 0 | R16: =COUNTIF(C16:O16,$R$4) -> 0 | S16: =COUNTIF(C16:O16,$S$4) -> 0 | T16: =SUM(P16:S16) -> 0
A17: 8 | B17: RAMIREZ FERNANDEZ NANCY | P17: =COUNTIF(C17:O17,$P$4) -> 0 | Q17: =COUNTIF(C17:O17,$Q$4) -> 0 | R17: =COUNTIF(C17:O17,$R$4) -> 0 | S17: =COUNTIF(C17:O17,$S$4) -> 0 | T17: =SUM(P17:S17) -> 0
A18: 9 | B18: RAMOS SANCHEZ DELFIN | P18: =COUNTIF(C18:O18,$P$4) -> 0 | Q18: =COUNTIF(C18:O18,$Q$4) -> 0 | R18: =COUNTIF(C18:O18,$R$4) -> 0 | S18: =COUNTIF(C18:O18,$S$4) -> 0 | T18: =SUM(P18:S18) -> 0
A19: 10 | B19: RIVERA QUISPE MARY ROSA DEL CARMEN | P19: =COUNTIF(C19:O19,$P$4) -> 0 | Q19: =COUNTIF(C19:O19,$Q$4) -> 0 | R19: =COUNTIF(C19:O19,$R$4) -> 0 | S19: =COUNTIF(C19:O19,$S$4) -> 0 | T19: =SUM(P19:S19) -> 0
A20: 11 | B20: RODAS VASQUEZ ARNULFO | P20: =COUNTIF(C20:O20,$P$4) -> 0 | Q20: =COUNTIF(C20:O20,$Q$4) -> 0 | R20: =COUNTIF(C20:O20,$R$4) -> 0 | S20: =COUNTIF(C20:O20,$S$4) -> 0 | T20: =SUM(P20:S20) -> 0
A21: 12 | B21: SALVADOR QUISPE DELFIN | P21: =COUNTIF(C21:O21,$P$4) -> 0 | Q21: =COUNTIF(C21:O21,$Q$4) -> 0 | R21: =COUNTIF(C21:O21,$R$4) -> 0 | S21: =COUNTIF(C21:O21,$S$4) -> 0 | T21: =SUM(P21:S21) -> 0
... A27: 18 | B27: AREA PRODUCTIVA | P27: =COUNTIF(C27:O27,$P$4) -> 0 | Q27: =COUNTIF(C27:O27,$Q$4) -> 0 | R27: =COUNTIF(C27:O27,$R$4) -> 0 | S27: =COUNTIF(C27:O27,$S$4) -> 0 | T27: =SUM(P27:S27) -> 0
A28: PERSONAL ADMINISTRATIVO
A29: 1 | B29: . CASTELLON MARLENE | P29: =COUNTIF(C29:O29,$P$4) -> 0 | Q29: =COUNTIF(C29:O29,$Q$4) -> 0 | R29: =COUNTIF(C29:O29,$R$4) -> 0 | S29: =COUNTIF(C29:O29,$S$4) -> 0 | T29: =SUM(P29:S29) -> 0
A30: 2 | B30: . ESPINOZA RUTH PAMELA | P30: =COUNTIF(C30:O30,$P$4) -> 0 | Q30: =COUNTIF(C30:O30,$Q$4) -> 0 | R30: =COUNTIF(C30:O30,$R$4) -> 0 | S30: =COUNTIF(C30:O30,$S$4) -> 0 | T30: =SUM(P30:S30) -> 0
A31: 3 | B31: FRIAS VALLEJOS RAMIRO ALEX | P31: =COUNTIF(C31:O31,$P$4) -> 0 | Q31: =COUNTIF(C31:O31,$Q$4) -> 0 | R31: =COUNTIF(C31:O31,$R$4) -> 0 | S31: =COUNTIF(C31:O31,$S$4) -> 0 | T31: =SUM(P31:S31) -> 0
A32: 4 | B32: FUERTES ROMERO NICANOR | P32: =COUNTIF(C32:O32,$P$4) -> 0 | Q32: =COUNTIF(C32:O32,$Q$4) -> 0 | R32: =COUNTIF(C32:O32,$R$4) -> 0 | S32: =COUNTIF(C32:O32,$S$4) -> 0 | T32: =SUM(P32:S32) -> 0
A33: 5 | B33: PEREZ GUERRA CARLOS MANUEL | P33: =COUNTIF(C33:O33,$P$4) -> 0 | Q33: =COUNTIF(C33:O33,$Q$4) -> 0 | R33: =COUNTIF(C33:O33,$R$4) -> 0 | S33: =COUNTIF(C33:O33,$S$4) -> 0 | T33: =SUM(P33:S33) -> 0
A34: 6 | B34: SENO ALDANA TEOFILO JORGE | P34: =COUNTIF(C34:O34,$P$4) -> 0 | Q34: =COUNTIF(C34:O34,$Q$4) -> 0 | R34: =COUNTIF(C34:O34,$R$4) -> 0 | S34: =COUNTIF(C34:O34,$S$4) -> 0 | T34: =SUM(P34:S34) -> 0
A35: 7 | B35: QUISPE LEVA TEODORO | P35: =COUNTIF(C35:O35,$P$4) -> 0 | Q35: =COUNTIF(C35:O35,$Q$4) -> 0 | R35: =COUNTIF(C35:O35,$R$4) -> 0 | S35: =COUNTIF(C35:O35,$S$4) -> 0 | T35: =SUM(P35:S35) -> 0
A36: 8 | B36: VILLARPANDO MAMANI ALISON | P36: =COUNTIF(C36:O36,$P$4) -> 0 | Q36: =COUNTIF(C36:O36,$Q$4) -> 0 | R36: =COUNTIF(C36:O36,$R$4) -> 0 | S36: =COUNTIF(C36:O36,$S$4) -> 0 | T36: =SUM(P36:S36) -> 0
B37: SECRETARIA DAF | P37: =COUNTIF(C37:O37,$P$4) -> 0 | Q37: =COUNTIF(C37:O37,$Q$4) -> 0 | R37: =COUNTIF(C37:O37,$R$4) -> 0 | S37: =COUNTIF(C37:O37,$S$4) -> 0 | T37: =SUM(P37:S37) -> 0
B38: SALUD PREVENTIVA | P38: =COUNTIF(C38:O38,$P$4) -> 0 | Q38: =COUNTIF(C38:O38,$Q$4) -> 0 | R38: =COUNTIF(C38:O38,$R$4) -> 0 | S38: =COUNTIF(C38:O38,$S$4) -> 0 | T38: =SUM(P38:S38) -> 0
A39: PERSONAL DE SERVICIO
A40: 1 | B40: CALDERON CASTELLON FERNANDO | P40: =COUNTIF(C40:O40,$P$4) -> 0 | Q40: =COUNTIF(C40:O40,$Q$4) -> 0 | R40: =COUNTIF(C40:O40,$R$4) -> 0 | S40: =COUNTIF(C40:O40,$S$4) -> 0 | T40: =SUM(P40:S40) -> 0
A41: 2 | B41: FERNANDEZ VELA JUAN | P41: =COUNTIF(C41:O41,$P$4) -> 0 | Q41: =COUNTIF(C41:O41,$Q$4) -> 0 | R41: =COUNTIF(C41:O41,$R$4) -> 0 | S41: =COUNTIF(C41:O41,$S$4) -> 0 | T41: =SUM(P41:S41) -> 0
A42: 3 | B42: FLORES CARRILLO SEVERINA | P42: =COUNTIF(C42:O42,$P$4) -> 0 | Q42: =COUNTIF(C42:O42,$Q$4) -> 0 | R42: =COUNTIF(C42:O42,$R$4) -> 0 | S42: =COUNTIF(C42:O42,$S$4) -> 0 | T42: =SUM(P42:S42) -> 0
A43: 4 | B43: HUARACHI CHUMACERO RODOLFO | P43: =COUNTIF(C43:O43,$P$4) -> 0 | Q43: =COUNTIF(C43:O43,$Q$4) -> 0 | R43: =COUNTIF(C43:O43,$R$4) -> 0 | S43: =COUNTIF(C43:O43,$S$4) -> 0 | T43: =SUM(P43:S43) -> 0
A44: 5 | B44: MARTINEZ ORTIZ EUGENIA | P44: =COUNTIF(C44:O44,$P$4) -> 0 | Q44: =COUNTIF(C44:O44,$Q$4) -> 0 | R44: =COUNTIF(C44:O44,$R$4) -> 0 | S44: =COUNTIF(C44:O44,$S$4) -> 0 | T44: =SUM(P44:S44) -> 0
A45: 6 | B45: MENDOZA FERNANDEZ ALBERTO | P45: =COUNTIF(C45:O45,$P$4) -> 0 | Q45: =COUNTIF(C45:O45,$Q$4) -> 0 | R45: =COUNTIF(C45:O45,$R$4) -> 0 | S45: =COUNTIF(C45:O45,$S$4) -> 0 | T45: =SUM(P45:S45) -> 0
...

Sheet ASISTENCIA 2
A1: PLANILLA DE ASISTENCIA
A2: Actividad: SOCIALIZACIÓN DE PROPUESTAS EN PLENARIA DE DOCUMENTOS NORMATIVOS Y CURRICULARES PARA LAS ESFM/UA Fecha: 23 de julio de 2025 Hora: 14:00
A3: N° | B3: APELLIDOS Y NOMBRES | C3: HORA | D3: FIRMA DE INICIO | E3: HORA | F3: FIRMA DE FINALIZACIÓN
A4: 1 | B4: =+'ASISTENCIA 1'!B5 -> QUISPE RICALDE SAUL
A5: 2 | B5: =+'ASISTENCIA 1'!B6 -> CALLAPA CRUZ ARMIN
A6: 3 | B6: =+'ASISTENCIA 1'!B7 -> ESPADA ARAMAYO LIZBETH CRISTEL
A7: 4 | B7: =+'ASISTENCIA 1'!B8 -> DURAN LOMAR ALBERTO
A8: 5 | B8: =+'ASISTENCIA 1'!B9 -> SAAVEDRA SALAZAR DIEGO
A9: PERSONAL DOCENTE
A10: 1 | B10: =+'ASISTENCIA 1'!B11 -> ARIAS CAYO ZULMA ABIGAIL
A11: 2 | B11: =+'ASISTENCIA 1'!B12 -> CALLE REQUENA GUILLERMINA LUZ
A12: 3 | B12: =+'ASISTENCIA 1'!B13 -> ILAFAYA CORONADO CLAUDIA
A13: 4 | B13: =+'ASISTENCIA 1'!B14 -> MACHACA MOLLO ELVIS JHONATHAN
A14: 5 | B14: =+'ASISTENCIA 1'!B15 -> MEDRANO QUISPE RUTH ELIZABETH
A15: 6 | B15: =+'ASISTENCIA 1'!B16 -> MENDOZA MOYA YOLANDA
A16: 7 | B16: =+'ASISTENCIA 1'!B17 -> MORENO ESCOBAR GLADYS MARIA
A17: 8 | B17: =+'ASISTENCIA 1'!B18 -> ORDOÑEZ ACEBO ELIAS JUSTO
A18: 9 | B18: =+'ASISTENCIA 1'!B19 -> QUISPE OLMEDO LEONARDO ARIEL
A19: 10 | B19: =+'ASISTENCIA 1'!B20 -> RAMIREZ FERNANDEZ NANCY
A20: 11 | B20: =+'ASISTENCIA 1'!B21 -> RAMOS SANCHEZ DELFIN
A21: 12 | B21: =+'ASISTENCIA 1'!B22 -> RIVERA QUISPE MARY ROSA DEL CARMEN
... A26: 17 | B26: =+'ASISTENCIA 1'!B27 -> YUCRA CRUZ SATURNINA
A27: PERSONAL ADMINISTRATIVO
A28: 1 | B28: =+'ASISTENCIA 1'!B30 -> . CASTELLON MARLENE
A29: 2 | B29: =+'ASISTENCIA 1'!B31 -> . ESPINOZA RUTH PAMELA
A30: 3 | B30: =+'ASISTENCIA 1'!B32 -> FRIAS VALLEJOS RAMIRO ALEX
A31: 4 | B31: =+'ASISTENCIA 1'!B33 -> FUERTES ROMERO NICANOR
A32: 5 | B32: =+'ASISTENCIA 1'!B34 -> LEON PERALTA ELSA NOEMI
A33: 6 | B33: =+'ASISTENCIA 1'!B35 -> MOREIRA MAMANI JHENNY MARIELA
A34: 7 | B34: =+'ASISTENCIA 1'!B36 -> PEREZ GUERRA CARLOS MANUEL
A35: 8 | B35: =+'ASISTENCIA 1'!B37 -> SENO ALDANA TEOFILO JORGE
A36: 9 | B36: =+'ASISTENCIA 1'!B38 -> QUISPE LEVA TEODORO
A37: 10 | B37: =+'ASISTENCIA 1'!B39 -> VILLARPANDO MAMANI ALISON
A38: PERSONAL DE SERVICIO
A39: 1 | B39: =+'ASISTENCIA 1'!B41 -> CALDERON CASTELLON FERNANDO
A40: 2 | B40: =+'ASISTENCIA 1'!B42 -> FERNANDEZ VELA JUAN
A41: 3 | B41: =+'ASISTENCIA 1'!B43 -> FLORES CARRILLO SEVERINA
A42: 4 | B42: =+'ASISTENCIA 1'!B44 -> HUARACHI CHUMACERO RODOLFO
A43: 5 | B43: =+'ASISTENCIA 1'!B45 -> MARTINEZ ORTIZ EUGENIA
A44: 6 | B44: =+'ASISTENCIA 1'!B46 -> MENDOZA FERNANDEZ ALBERTO
...

Sheet ASIS_EST

Sheet AÑO NUEVO
A2: AÑO NUEVO ANDINO AMAZONICO CHAQUEÑO 5533
A3: N° | B3: APELLIDOS Y NOMBRES | C3: RESPONSABLES | D3: REGIÓN
A4: 1 | B4: ILAFAYA CORONADO CLAUDIA | C4: RESPONSABLE | D4: AMAZONICO | F4: 1
A5: 2 | B5: MEDRANO QUISPE RUTH ELIZABETH | C5: RESPONSABLE | D5: AMAZONICO | F5: 1
A6: 3 | B6: YUCRA CRUZ SATURNINA | C6: RESPONSABLE | D6: AMAZONICO | F6: 1
A7: 4 | B7: CALLAPA CRUZ ARMIN | D7: AMAZONICO | F7: 1
A8: 5 | B8: CALLE REQUENA GUILLERMINA LUZ | D8: AMAZONICO | F8: 1
A9: 6 | B9: SAAVEDRA SALAZAR DIEGO | D9: AMAZONICO | F9: 1
A10: 7 | B10: LEON PERALTA ELSA NOEMI | D10: AMAZONICO | F10: 1
A11: 8 | B11: MARTINEZ ORTIZ EUGENIA | D11: AMAZONICO | F11: 1
A12: 9 | B12: FERNANDEZ VELA JUAN | D12: AMAZONICO | F12: 1
A13: 10 | B13: MOREIRA MAMANI JHENNY MARIELA | D13: AMAZONICO | F13: 1
A14: 11 | B14: QUISPE LEVA TEODORO | D14: AMAZONICO | F14: 1
A15: 12 | B15: RAMOS SANCHEZ DELFIN | D15: AMAZONICO | F15: 1
A16: 13 | B16: RODAS VASQUEZ ARNULFO | D16: AMAZONICO | F16: 1
A17: 1 | B17: MORENO ESCOBAR GLADYS MARIA | C17: RESPONSABLE | D17: ANDINO | E17: 1
A18: 2 | B18: SALVADOR QUISPE DELFIN | C18: RESPONSABLE | D18: ANDINO | E18: 1
A19: 3 | B19: TARDIO CONDORI MARIBEL | C19: RESPONSABLE | D19: ANDINO | E19: 1
A20: 4 | B20: QUISPE OLMEDO LEONARDO ARIEL | C20: RESPONSABLE | D20: ANDINO | E20: 1
A21: 5 | B21: HUARACHI CHUMACERO RODOLFO | D21: ANDINO | E21: 1
A22: 6 | B22: CALDERON CASTELLON FERNANDO | D22: ANDINO | E22: 1
A23: 7 | B23: QUISPE RICALDE SAUL | D23: ANDINO | E23: 1
A24: 8 | B24: . CASTELLON MARLENE | D24: ANDINO | E24: 1
A25: 9 | B25: . ESPINOZA RUTH PAMELA | D25: ANDINO | E25: 1
A26: 10 | B26: FRIAS VALLEJOS RAMIRO ALEX | D26: ANDINO | E26: 1
A27: 11 | B27: ORDOÑEZ ACEBO ELIAS JUSTO | D27: ANDINO | E27: 1
A28: 12 | B28: DURAN LOMAR ALBERTO | D28: ANDINO | E28: 1
A29: 13 | B29: RIVERA QUISPE MARY ROSA DEL CARMEN | D29: ANDINO | E29: 1
A30: 1 | B30: MENDOZA MOYA YOLANDA | C30: RESPONSABLE | D30: CHAQUEÑO | G30: 1
A31: 2 | B31: RAMIREZ FERNANDEZ NANCY | C31: RESPONSABLE | D31: CHAQUEÑO | G31: 1
A32: 3 | B32: ARIAS CAYO ZULMA ABIGAIL | D32: CHAQUEÑO | G32: 1
A33: 4 | B33: FLORES CARRILLO SEVERINA | D33: CHAQUEÑO | G33: 1
A34: 5 | B34: ESPADA ARAMAYO LIZBETH CRISTEL | D34: CHAQUEÑO | G34: 1
A35: 6 | B35: MACHACA MOLLO ELVIS JHONATHAN | D35: CHAQUEÑO | G35: 1
A36: 7 | B36: FUERTES ROMERO NICANOR | D36: CHAQUEÑO | G36: 1
A37: 8 | B37: MENDOZA FERNANDEZ ALBERTO | D37: CHAQUEÑO | G37: 1
A38: 9 | B38: PEREZ GUERRA CARLOS MANUEL | D38: CHAQUEÑO | G38: 1
A39: 10 | B39: PANTOJA ARANCIBIA JUSTINO | D39: CHAQUEÑO | G39: 1
A40: 11 | B40: SENO ALDANA TEOFILO JORGE | D40: CHAQUEÑO | G40: 1
A41: 12 | B41: VILLARPANDO MAMANI ALISON | D41: CHAQUEÑO | G41: 1
...

Sheet ASIS_OTROS
A1: Planilla de Asistencia
A2: Actividad: REUNIÓN INSTITUCIONAL Fecha: miercoles, 25 de febrero de 2025 Hora: 15:30 - SOLO ESTUDIANTES
A3: N° | B3: APELLIDOS Y NOMBRES | C3: AÑO DE FORMACIÓN | D3: ESPECIALIDAD | E3: FIRMA DE ASISTENCIA
A4: 1
A5: 2
A6: 3
A7: 4
A8: 5
A9: 6
A10: 7
A11: 8
A12: 9
A13: 10
A14: 11
A15: 12
... A32: 29

Sheet COMISIONES1
A1: COMISIONES INTERNAS 2025
A3: N° | B3: APELLIDOS Y NOMBRES | C3: COMISIÓN
A4: 1 | B4: . CASTELLON MARLENE | C4: CULTURA
A5: 3 | B5: MACHACA MOLLO ELVIS JHONATHAN | C5: CULTURA
A6: 4 | B6: MENDOZA MOYA YOLANDA | C6: CULTURA
A7: 2 | B7: MORENO ESCOBAR GLADYS MARIA | C7: CULTURA
A8: 5 | B8: SAAVEDRA SALAZAR DIEGO | C8: CULTURA
A9: 6 | B9: SALVADOR QUISPE DELFIN | C9: CULTURA
A10: 7 | B10: SENO ALDANA TEOFILO JORGE | C10: CULTURA
A11: 8 | B11: DOCENTE AREA PRODUCTIVA | C11: DEPORTE
A12: 9 | B12: HUARACHI CHUMACERO RODOLFO | C12: DEPORTE
A13: 12 | B13: MOREIRA MAMANI JHENNY MARIELA | C13: DEPORTE
A14: 11 | B14: QUISPE LEVA TEODORO | C14: DEPORTE
A15: 10 | B15: YUCRA CRUZ SATURNINA | C15: DEPORTE
... A43: 40 | B43: TARDIO CONDORI MARIBEL | C43: SOCIAL

Sheet APORTES
A1: PROPUESTA 1 | I1: PROPUESTA 2 | R1: PROPUESTA 3
A3: A | B3: A | C3: H/P | D3: H/P | E3: A | I3: A | J3: A | K3: H/P | L3: H/P | M3: A | R3: A | S3: A | T3: H/P | U3: H/P | V3: A
A4: QUISPE RICALDE SAUL | B4: DIRECTIVO | C4: 15060 | D4: =C4 -> 15060 | E4: =$G$6*D4 -> 10.251459 | F4: H/P TOTAL | G4: =SUM(D4:D47) -> 293811.85 | I4: QUISPE RICALDE SAUL | J4: DIRECTIVO | K4: =+C4 -> 15060 | L4: 4 | M4: =$P$6*L4 -> 175.82418 | N4: H/P TOTAL | P4: =SUM(L4:L47) -> 91 | R4: QUISPE RICALDE SAUL | S4: DIRECTIVO | T4: =+K4 -> 15060 | U4: 6 | V4: =$Y$6*U4 -> 165.51724 | W4: H/P TOTAL | Y4: =SUM(U4:U47) -> 145
A5: CALLAPA CRUZ ARMIN | B5: DIRECTIVO | C5: 13930 | D5: =C5 -> 13930 | E5: =$G$6*D5 -> 9.4822588 | F5: MONTO DE CUOTA | G5: 200 | I5: CALLAPA CRUZ ARMIN | J5: DIRECTIVO | K5: =+C5 -> 13930 | L5: 4 | M5: =$P$6*L5 -> 175.82418 | N5: MONTO/CUOTA | P5: 4000 | R5: CALLAPA CRUZ ARMIN | S5: DIRECTIVO | T5: =+K5 -> 13930 | U5: 6 | V5: =$Y$6*U5 -> 165.51724 | W5: MONTO/CUOTA | Y5: 4000
A6: ESPADA ARAMAYO LIZBETH CRISTEL | B6: DIRECTIVO | C6: 9325.6 | D6: =C6 -> 9325.6 | E6: =$G$6*D6 -> 6.3480081 | F6: MONTO | G6: =G5/G4 -> 0.00068070774 | I6: ESPADA ARAMAYO LIZBETH CRISTEL | J6: DIRECTIVO | K6: =+C6 -> 9325.6 | L6: 3 | M6: =$P$6*L6 -> 131.86813 | N6: MONTO | P6: =P5/P4 -> 43.956044 | R6: ESPADA ARAMAYO LIZBETH CRISTEL | S6: DIRECTIVO | T6: =+K6 -> 9325.6 | U6: 5 | V6: =$Y$6*U6 -> 137.93103 | W6: MONTO | Y6: =Y5/Y4 -> 27.586207
A7: DURAN LOMAR ALBERTO | B7: DIRECTIVO | C7: 8339.7 | D7: =C7 -> 8339.7 | E7: =$G$6*D7 -> 5.6768983 | I7: DURAN LOMAR ALBERTO | J7: DIRECTIVO | K7: =+C7 -> 8339.7 | L7: 3 | M7: =$P$6*L7 -> 131.86813 | R7: DURAN LOMAR ALBERTO | S7: DIRECTIVO | T7: =+K7 -> 8339.7 | U7: 4 | V7: =$Y$6*U7 -> 110.34483
A8: UYUQUIPA FAJARDO JORGE | B8: DIRECTIVO | C8: 11317 | D8: =C8 -> 11317 | E8: =$G$6*D8 -> 7.7035695 | I8: UYUQUIPA FAJARDO JORGE | J8: DIRECTIVO | K8: =+C8 -> 11317 | L8: 3 | M8: =$P$6*L8 -> 131.86813 | N8: De bs. | O8: A bs. | P8: Clasif. | R8: UYUQUIPA FAJARDO JORGE | S8: DIRECTIVO | T8: =+K8 -> 11317 | U8: 5 | V8: =$Y$6*U8 -> 137.93103 | W8: De bs. | X8: A bs. | Y8: Clasif.
K9: =+C9 -> 0 | N9: 2000 | O9: 4000 | P9: 1 | T9: =+K9 -> 0 | W9: 2000 | X9: 3000 | Y9: 1
K10: =+C10 -> 0 | N10: 4001 | O10: 8000 | P10: 2 | T10: =+K10 -> 0 | W10: 3001 | X10: 4000 | Y10: 2
A11: ARIAS CAYO ZULMA ABIGAIL | B11: DOCENTE | C11: 9603 | D11: =C11 -> 9603 | E11: =$G$6*D11 -> 6.5368364 | I11: ARIAS CAYO ZULMA ABIGAIL | J11: DOCENTE | K11: =+C11 -> 9603 | L11: 3 | M11: =$P$6*L11 -> 131.86813 | N11: 8001 | O11: 12000 | P11: 3 | R11: ARIAS CAYO ZULMA ABIGAIL | S11: DOCENTE | T11: =+K11 -> 9603 | U11: 5 | V11: =$Y$6*U11 -> 137.93103 | W11: 4001 | X11: 6000 | Y11: 3
A12: CALLE REQUENA GUILLERMINA LUZ | B12: DOCENTE | C12: 13459.5 | D12: =C12 -> 13459.5 | E12: =$G$6*D12 -> 9.1619858 | I12: CALLE REQUENA GUILLERMINA LUZ | J12: DOCENTE | K12: =+C12 -> 13459.5 | L12: 4 | M12: =$P$6*L12 -> 175.82418 | N12: 12001 | O12: 16000 | P12: 4 | R12: CALLE REQUENA GUILLERMINA LUZ | S12: DOCENTE | T12: =+K12 -> 13459.5 | U12: 6 | V12: =$Y$6*U12 -> 165.51724 | W12: 6001 | X12: 9000 | Y12: 4
A13: ESPINOZA MAYGUA DIVINA | B13: DOCENTE | C13: 12388.25 | D13: =C13 -> 12388.25 | E13: =$G$6*D13 -> 8.4327776 | I13: ESPINOZA MAYGUA DIVINA | J13: DOCENTE | K13: =+C13 -> 12388.25 | L13: 4 | M13: =$P$6*L13 -> 175.82418 | R13: ESPINOZA MAYGUA DIVINA | S13: DOCENTE | T13: =+K13 -> 12388.25 | U13: 6 | V13: =$Y$6*U13 -> 165.51724 | W13: 9001 | X13: 12000 | Y13: 5
A14: GRAZ NUÑEZ REYNA MARTHA | B14: DOCENTE | C14: 9603 | D14: =C14 -> 9603 | E14: =$G$6*D14 -> 6.5368364 | I14: GRAZ NUÑEZ REYNA MARTHA | J14: DOCENTE | K14: =+C14 -> 9603 | L14: 3 | M14: =$P$6*L14 -> 131.86813 | R14: GRAZ NUÑEZ REYNA MARTHA | S14: DOCENTE | T14: =+K14 -> 9603 | U14: 5 | V14: =$Y$6*U14 -> 137.93103 | W14: 12001 | X14: 16000 | Y14: 6
A15: ILAFAYA CORONADO CLAUDIA | B15: DOCENTE | C15: 10245.75 | D15: =C15 -> 10245.75 | E15: =$G$6*D15 -> 6.9743613 | I15: ILAFAYA CORONADO CLAUDIA | J15: DOCENTE | K15: =+C15 -> 10245.75 | L15: 3 | M15: =$P$6*L15 -> 131.86813 | R15: ILAFAYA CORONADO CLAUDIA | S15: DOCENTE | T15: =+K15 -> 10245.75 | U15: 5 | V15: =$Y$6*U15 -> 137.93103 | Y15: 7
A16: MEDRANO QUISPE RUTH ELIZABETH | B16: DOCENTE | C16: 11317 | D16: =C16 -> 11317 | E16: =$G$6*D16 -> 7.7035695 | I16: MEDRANO QUISPE RUTH ELIZABETH | J16: DOCENTE | K16: =+C16 -> 11317 | L16: 3 | M16: =$P$6*L16 -> 131.86813 | R16: MEDRANO QUISPE RUTH ELIZABETH | S16: DOCENTE | T16: =+K16 -> 11317 | U16: 5 | V16: =$Y$6*U16 -> 137.93103
A17: MORENO ESCOBAR GLADYS MARIA | B17: DOCENTE | C17: 9603 | D17: =C17 -> 9603 | E17: =$G$6*D17 -> 6.5368364 | I17: MORENO ESCOBAR GLADYS MARIA | J17: DOCENTE | K17: =+C17 -> 9603 | L17: 3 | M17: =$P$6*L17 -> 131.86813 | R17: MORENO ESCOBAR GLADYS MARIA | S17: DOCENTE | T17: =+K17 -> 9603 | U17: 5 | V17: =$Y$6*U17 -> 137.93103
A18: QUISPE OLMEDO LEONARDO ARIEL | B18: DOCENTE | C18: 9603 | D18: =C18 -> 9603 | E18: =$G$6*D18 -> 6.5368364 | I18: QUISPE OLMEDO LEONARDO ARIEL | J18: DOCENTE | K18: =+C18 -> 9603 | L18: 3 | M18: =$P$6*L18 -> 131.86813 | R18: QUISPE OLMEDO LEONARDO ARIEL | S18: DOCENTE | T18: =+K18 -> 9603 | U18: 5 | V18: =$Y$6*U18 -> 137.93103
A19: RAMIREZ FERNANDEZ NANCY | B19: DOCENTE | C19: 13459.5 | D19: =C19 -> 13459.5 | E19: =$G$6*D19 -> 9.1619858 | I19: RAMIREZ FERNANDEZ NANCY | J19: DOCENTE | K19: =+C19 -> 13459.5 | L19: 4 | M19: =$P$6*L19 -> 175.82418 | R19: RAMIREZ FERNANDEZ NANCY | S19: DOCENTE | T19: =+K19 -> 13459.5 | U19: 6 | V19: =$Y$6*U19 -> 165.51724
A20: RIVERA QUISPE MARY ROSA DEL CARMEN | B20: DOCENTE | C20: 12388.25 | D20: =C20 -> 12388.25 | E20: =$G$6*D20 -> 8.4327776 | I20: RIVERA QUISPE MARY ROSA DEL CARMEN | J20: DOCENTE | K20: =+C20 -> 12388.25 | L20: 4 | M20: =$P$6*L20 -> 175.82418 | R20: RIVERA QUISPE MARY ROSA DEL CARMEN | S20: DOCENTE | T20: =+K20 -> 12388.25 | U20: 6 | V20: =$Y$6*U20 -> 165.51724
A21: SAAVEDRA SALAZAR DIEGO | B21: DOCENTE | C21: 13459.5 | D21: =C21 -> 13459.5 | E21: =$G$6*D21 -> 9.1619858 | I21: SAAVEDRA SALAZAR DIEGO | J21: DOCENTE | K21: =+C21 -> 13459.5 | L21: 4 | M21: =$P$6*L21 -> 175.82418 | R21: SAAVEDRA SALAZAR DIEGO | S21: DOCENTE | T21: =+K21 -> 13459.5 | U21: 6 | V21: =$Y$6*U21 -> 165.51724
A22: SALVADOR QUISPE DELFIN | B22: DOCENTE | C22: 12388.25 | D22: =C22 -> 12388.25 | E22: =$G$6*D22 -> 8.4327776 | I22: SALVADOR QUISPE DELFIN | J22: DOCENTE | K22: =+C22 -> 12388.25 | L22: 4 | M22: =$P$6*L22 -> 175.82418 | R22: SALVADOR QUISPE DELFIN | S22: DOCENTE | T22: =+K22 -> 12388.25 | U22: 6 | V22: =$Y$6*U22 -> 165.51724
A23: SOLIZ RENGIFO CESAR | B23: DOCENTE | C23: 8960 | D23: =C23 -> 8960 | E23: =$G$6*D23 -> 6.0991413 | I23: SOLIZ RENGIFO CESAR | J23: DOCENTE | K23: =+C23 -> 8960 | L23: 3 | M23: =$P$6*L23 -> 131.86813 | R23: SOLIZ RENGIFO CESAR | S23: DOCENTE | T23: =+K23 -> 8960 | U23: 4 | V23: =$Y$6*U23 -> 110.34483
A24: TARDIO CONDORI MARIBEL | B24: DOCENTE | C24: 9603 | D24: =C24 -> 9603 | E24: =$G$6*D24 -> 6.5368364 | I24: TARDIO CONDORI MARIBEL | J24: DOCENTE | K24: =+C24 -> 9603 | L24: 3 | M24: =$P$6*L24 -> 131.86813 | R24: TARDIO CONDORI MARIBEL | S24: DOCENTE | T24: =+K24 -> 9603 | U24: 5 | V24: =$Y$6*U24 -> 137.93103
A25: TORRES ORTUÑO PAMELA | B25: DOCENTE | C25: 8960.25 | D25: =C25 -> 8960.25 | E25: =$G$6*D25 -> 6.0993115 | I25: TORRES ORTUÑO PAMELA | J25: DOCENTE | K25: =+C25 -> 8960.25 | L25: 3 | M25: =$P$6*L25 -> 131.86813 | R25: TORRES ORTUÑO PAMELA | S25: DOCENTE | T25: =+K25 -> 8960.25 | U25: 4 | V25: =$Y$6*U25 -> 110.34483
A26: YUCRA CRUZ SATURNINA | B26: DOCENTE | C26: 9603 | D26: =C26 -> 9603 | E26: =$G$6*D26 -> 6.5368364 | I26: YUCRA CRUZ SATURNINA | J26: DOCENTE | K26: =+C26 -> 9603 | L26: 3 | M26: =$P$6*L26 -> 131.86813 | R26: YUCRA CRUZ SATURNINA | S26: DOCENTE | T26: =+K26 -> 9603 | U26: 5 | V26: =$Y$6*U26 -> 137.93103
K27: =+C27 -> 0 | T27: =+K27 -> 0
K28: =+C28 -> 0 | T28: =+K28 -> 0
A29: . CASTELLON MARLENE | B29: ADMINISTRATIVO | C29: 3771 | D29: =C29 -> 3771 | E29: =$G$6*D29 -> 2.5669489 | I29: . CASTELLON MARLENE | J29: ADMINISTRATIVO | K29: =+C29 -> 3771 | L29: 1 | M29: =$P$6*L29 -> 43.956044 | R29: . CASTELLON MARLENE | S29: ADMINISTRATIVO | T29: =+K29 -> 3771 | U29: 2 | V29: =$Y$6*U29 -> 55.172414
A30: . ESPINOZA RUTH PAMELA | B30: ADMINISTRATIVO | C30: 3016 | D30: =C30 -> 3016 | E30: =$G$6*D30 -> 2.0530145 | I30: . ESPINOZA RUTH PAMELA | J30: ADMINISTRATIVO | K30: =+C30 -> 3016 | L30: 1 | M30: =$P$6*L30 -> 43.956044 | R30: . ESPINOZA RUTH PAMELA | S30: ADMINISTRATIVO | T30: =+K30 -> 3016 | U30: 2 | V30: =$Y$6*U30 -> 55.172414
A31: . HEREDIA RAMIRO | B31: ADMINISTRATIVO | C31: 3771 | D31: =C31 -> 3771 | E31: =$G$6*D31 -> 2.5669489 | I31: . HEREDIA RAMIRO | J31: ADMINISTRATIVO | K31: =+C31 -> 3771 | L31: 1 | M31: =$P$6*L31 -> 43.956044 | R31: . HEREDIA RAMIRO | S31: ADMINISTRATIVO | T31: =+K31 -> 3771 | U31: 2 | V31: =$Y$6*U31 -> 55.172414
A32: CHAVEZ ZEBALLOS ELIZABETH | B32: ADMINISTRATIVO | C32: 3016 | D32: =C32 -> 3016 | E32: =$G$6*D32 -> 2.0530145 | I32: CHAVEZ ZEBALLOS ELIZABETH | J32: ADMINISTRATIVO | K32: =+C32 -> 3016 | L32: 1 | M32: =$P$6*L32 -> 43.956044 | R32: CHAVEZ ZEBALLOS ELIZABETH | S32: ADMINISTRATIVO | T32: =+K32 -> 3016 | U32: 2 | V32: =$Y$6*U32 -> 55.172414
A33: FRIAS VALLEJOS RAMIRO ALEX | B33: ADMINISTRATIVO | C33: 3016 | D33: =C33 -> 3016 | E33: =$G$6*D33 -> 2.0530145 | I33: FRIAS VALLEJOS RAMIRO ALEX | J33: ADMINISTRATIVO | K33: =+C33 -> 3016 | L33: 1 | M33: =$P$6*L33 -> 43.956044 | R33: FRIAS VALLEJOS RAMIRO ALEX | S33: ADMINISTRATIVO | T33: =+K33 -> 3016 | U33: 2 | V33: =$Y$6*U33 -> 55.172414
A34: FUERTES ROMERO NICANOR | B34: ADMINISTRATIVO | C34: 4902.3 | D34: =C34 -> 4902.3 | E34: =$G$6*D34 -> 3.3370335 | I34: FUERTES ROMERO NICANOR | J34: ADMINISTRATIVO | K34: =+C34 -> 4902.3 | L34: 2 | M34: =$P$6*L34 -> 87.912088 | R34: FUERTES ROMERO NICANOR | S34: ADMINISTRATIVO | T34: =+K34 -> 4902.3 | U34: 3 | V34: =$Y$6*U34 -> 82.758621
A35: PEREZ GUERRA CARLOS MANUEL | B35: ADMINISTRATIVO | C35: 3771 | D35: =C35 -> 3771 | E35: =$G$6*D35 -> 2.5669489 | I35: PEREZ GUERRA CARLOS MANUEL | J35: ADMINISTRATIVO | K35: =+C35 -> 3771 | L35: 1 | M35: =$P$6*L35 -> 43.956044 | R35: PEREZ GUERRA CARLOS MANUEL | S35: ADMINISTRATIVO | T35: =+K35 -> 3771 | U35: 2 | V35: =$Y$6*U35 -> 55.172414
A36: SENO ALDANA TEOFILO JORGE | B36: ADMINISTRATIVO | C36: 3394 | D36: =C36 -> 3394 | E36: =$G$6*D36 -> 2.3103221 | I36: SENO ALDANA TEOFILO JORGE | J36: ADMINISTRATIVO | K36: =+C36 -> 3394 | L36: 1 | M36: =$P$6*L36 -> 43.956044 | R36: SENO ALDANA TEOFILO JORGE | S36: ADMINISTRATIVO | T36: =+K36 -> 3394 | U36: 2 | V36: =$Y$6*U36 -> 55.172414
A37: TOCO BERNAL FRANZ EDEL | B37: ADMINISTRATIVO | C37: 3394 | D37: =C37 -> 3394 | E37: =$G$6*D37 -> 2.3103221 | I37: TOCO BERNAL FRANZ EDEL | J37: ADMINISTRATIVO | K37: =+C37 -> 3394 | L37: 1 | M37: =$P$6*L37 -> 43.956044 | R37: TOCO BERNAL FRANZ EDEL | S37: ADMINISTRATIVO | T37: =+K37 -> 3394 | U37: 2 | V37: =$Y$6*U37 -> 55.172414
A38: VILLARPANDO MAMANI ALISON | B38: ADMINISTRATIVO | C38: 3394 | D38: =C38 -> 3394 | E38: =$G$6*D38 -> 2.3103221 | I38: VILLARPANDO MAMANI ALISON | J38: ADMINISTRATIVO | K38: =+C38 -> 3394 | L38: 1 | M38: =$P$6*L38 -> 43.956044 | R38: VILLARPANDO MAMANI ALISON | S38: ADMINISTRATIVO | T38: =+K38 -> 3394 | U38: 2 | V38: =$Y$6*U38 -> 55.172414
K39: =+C39 -> 0 | T39: =+K39 -> 0
K40: =+C40 -> 0 | T40: =+K40 -> 0
A41: CALDERON CASTELLON FERNANDO | B41: SERVICIO | C41: 3250 | D41: =C41 -> 3250 | E41: =$G$6*D41 -> 2.2123002 | I41: CALDERON CASTELLON FERNANDO | J41: SERVICIO | K41: =+C41 -> 3250 | L41: 1 | M41: =$P$6*L41 -> 43.956044 | R41: CALDERON CASTELLON FERNANDO | S41: SERVICIO | T41: =+K41 -> 3250 | U41: 2 | V41: =$Y$6*U41 -> 55.172414
...

Sheet APORTES1
A1: APORTES
A2: Motivo: __________________________________ | D2: Fecha:___/___/_____
A3: # | B3: NOMBRES Y APELLIDOS | C3: CARGO | D3: MONTO | E3: FIRMA DE CANCELACIÓN
A4: 1 | B4: QUISPE RICALDE SAUL | C4: DIRECTIVO
A5: 2 | B5: CALLAPA CRUZ ARMIN | C5: DIRECTIVO | E5: 1
A6: 3 | B6: ESPADA ARAMAYO LIZBETH CRISTEL | C6: DIRECTIVO
A7: 4 | B7: DURAN LOMAR ALBERTO | C7: DIRECTIVO
A8: 5 | B8: UYUQUIPA FAJARDO JORGE | C8: DIRECTIVO | E8: 1
A9: 6 | B9: ARIAS CAYO ZULMA ABIGAIL | C9: DOCENTE
A10: 7 | B10: CALLE REQUENA GUILLERMINA LUZ | C10: DOCENTE
A11: 8 | B11: ESPINOZA MAYGUA DIVINA | C11: DOCENTE
A12: 9 | B12: GRAZ NUÑEZ REYNA MARTHA | C12: DOCENTE
A13: 10 | B13: ILAFAYA CORONADO CLAUDIA | C13: DOCENTE | E13: 1
A14: 11 | B14: MEDRANO QUISPE RUTH ELIZABETH | C14: DOCENTE
A15: 12 | B15: MORENO ESCOBAR GLADYS MARIA | C15: DOCENTE
A16: 13 | B16: QUISPE OLMEDO LEONARDO ARIEL | C16: DOCENTE | E16: 1
A17: 14 | B17: RAMIREZ FERNANDEZ NANCY | C17: DOCENTE
A18: 15 | B18: RIVERA QUISPE MARY ROSA DEL CARMEN | C18: DOCENTE
A19: 16 | B19: SAAVEDRA SALAZAR DIEGO | C19: DOCENTE
A20: 17 | B20: SALVADOR QUISPE DELFIN | C20: DOCENTE
A21: 18 | B21: SOLIZ RENGIFO CESAR | C21: DOCENTE
A22: 19 | B22: TARDIO CONDORI MARIBEL | C22: DOCENTE
A23: 20 | B23: TORRES ORTUÑO PAMELA | C23: DOCENTE | E23: 1
A24: 21 | B24: YUCRA CRUZ SATURNINA | C24: DOCENTE
A25: 22 | B25: . CASTELLON MARLENE | C25: ADMINISTRATIVO
A26: 23 | B26: . ESPINOZA RUTH PAMELA | C26: ADMINISTRATIVO
A27: 24 | B27: . HEREDIA RAMIRO | C27: ADMINISTRATIVO | E27: 1
A28: 25 | B28: CHAVEZ ZEBALLOS ELIZABETH | C28: ADMINISTRATIVO
A29: 26 | B29: FRIAS VALLEJOS RAMIRO ALEX | C29: ADMINISTRATIVO | E29: 1
A30: 27 | B30: FUERTES ROMERO NICANOR | C30: ADMINISTRATIVO
A31: 28 | B31: PEREZ GUERRA CARLOS MANUEL | C31: ADMINISTRATIVO
A32: 29 | B32: SENO ALDANA TEOFILO JORGE | C32: ADMINISTRATIVO | E32: 1
A33: 30 | B33: TOCO BERNAL FRANZ EDEL | C33: ADMINISTRATIVO
A34: 31 | B34: VILLARPANDO MAMANI ALISON | C34: ADMINISTRATIVO | E34: 1
A35: 32 | B35: CALDERON CASTELLON FERNANDO | C35: SERVICIO
A36: 33 | B36: FERNANDEZ VELA JUAN | C36: SERVICIO
A37: 34 | B37: FLORES CARRILLO SEVERINA | C37: SERVICIO
A38: 35 | B38: HUARACHI CHUMACERO RODOLFO | C38: SERVICIO
A39: 36 | B39: MARTINEZ ORTIZ EUGENIA | C39: SERVICIO
A40: 37 | B40: MENDOZA FERNANDEZ ALBERTO | C40: SERVICIO
...

Sheet PRESENTACION
A1: PLANILLA DE ASISTENCIA
A3: N° | B3: APELLIDOS Y NOMBRES | C3: MEM | D3: DJ
A4: 1 | B4: QUISPE RICALDE SAUL
A5: 2 | B5: CALLAPA CRUZ ARMIN
A6: 3 | B6: ESPADA ARAMAYO LIZBETH CRISTEL
A7: 4 | B7: DURAN LOMAR ALBERTO
A8: 5 | B8: UYUQUIPA FAJARDO JORGE
A9: PERSONAL DOCENTE
A10: 1 | B10: ARIAS CAYO ZULMA ABIGAIL
A11: 2 | B11: CALLE REQUENA GUILLERMINA LUZ
A12: 3 | B12: ESPINOZA MAYGUA DIVINA
A13: 4 | B13: GRAZ NUÑEZ REYNA MARTHA
A14: 5 | B14: ILAFAYA CORONADO CLAUDIA
A15: 6 | B15: MEDRANO QUISPE RUTH ELIZABETH
A16: 7 | B16: MORENO ESCOBAR GLADYS MARIA
A17: 8 | B17: QUISPE OLMEDO LEONARDO ARIEL
A18: 9 | B18: RAMIREZ FERNANDEZ NANCY
A19: 10 | B19: RIVERA QUISPE MARY ROSA DEL CARMEN
A20: 11 | B20: SAAVEDRA SALAZAR DIEGO
A21: 12 | B21: SALVADOR QUISPE DELFIN
... A25: 16 | B25: YUCRA CRUZ SATURNINA
A26: PERSONAL ADMINISTRATIVO
A27: 1 | B27: . CASTELLON MARLENE
A28: 2 | B28: . ESPINOZA RUTH PAMELA
A29: 3 | B29: . HEREDIA RAMIRO
A30: 4 | B30: CHAVEZ ZEBALLOS ELIZABETH
A31: 5 | B31: FRIAS VALLEJOS RAMIRO ALEX
A32: 6 | B32: FUERTES ROMERO NICANOR
A33: 7 | B33: PEREZ GUERRA CARLOS MANUEL
A34: 8 | B34: SENO ALDANA TEOFILO JORGE
A35: 9 | B35: TOCO BERNAL FRANZ EDEL
A36: 10 | B36: VILLARPANDO MAMANI ALISON
A37: PERSONAL DE SERVICIO
A38: 1 | B38: CALDERON CASTELLON FERNANDO
A39: 2 | B39: FERNANDEZ VELA JUAN
A40: 3 | B40: FLORES CARRILLO SEVERINA
A41: 4 | B41: HUARACHI CHUMACERO RODOLFO
A42: 5 | B42: MARTINEZ ORTIZ EUGENIA
A43: 6 | B43: MENDOZA FERNANDEZ ALBERTO
A44: 7 | B44: PANTOJA ARANCIBIA JUSTINO

Sheet CUMPLIMINETO
B3: N° | C3: APELLIDOS Y NOMBRES | D3: OBSERVACIÓN
B4: 1 | C4: QUISPE RICALDE SAUL
B5: 2 | C5: CALLAPA CRUZ ARMIN
B6: 3 | C6: ESPADA ARAMAYO LIZBETH CRISTEL
B7: 4 | C7: DURAN LOMAR ALBERTO
B8: 5 | C8: SAAVEDRA SALAZAR DIEGO
B9: 1 | C9: ARIAS CAYO ZULMA ABIGAIL
B10: 2 | C10: CALLE REQUENA GUILLERMINA LUZ
B11: 3 | C11: ILAFAYA CORONADO CLAUDIA
B12: 4 | C12: MACHACA MOLLO ELVIS JHONATHAN
B13: 5 | C13: MEDRANO QUISPE RUTH ELIZABETH
B14: 6 | C14: MENDOZA MOYA YOLANDA
B15: 7 | C15: MORENO ESCOBAR GLADYS MARIA
... B41: 7 | C41: PANTOJA ARANCIBIA JUSTINO
